Workbook

Sheet Base de Dados
A1: ="Base de dados — previsões do mês · "&$B$3 -> Base de dados — previsões do mês · [Nome do cliente]
A2: Preencha só as células amarelas (letras azuis). Todas as outras abas se calculam sozinhas a partir daqui.
A3: Cliente / profissional | B3: [Nome do cliente]
A4: Mês de referência (1º dia do mês) | B4: 46296 | C4: Qualquer dia do mês serve; a planilha usa o mês inteiro.
A5: Investimento previsto (R$) | B5: 30000 | C5: Quanto será investido em anúncios no mês.
A6: Data de hoje (para saber o que já passou) | B6: =TODAY() -> 46308 | C6: Vem da data do computador. Para simular outro dia, digite a data (azul).
A7: Reduzir as metas seguintes quando eu superar a meta? | B7: Não | C7: "Não": a meta só sobe quando fico abaixo. "Sim": ela também cai quando eu supero.
A9: Etapa | B9: Como definir | C9: Valor previsto | D9: Unidade do valor | E9: Meta do mês (nº) | F9: Custo por unidade (R$) | G9: % da etapa anterior | H9: Alerta
A10: Lead | B10: Custo | C10: 35 | D10: =IF(B10="Custo","R$ por "&LOWER(A10),IF(B10="Porcentagem","% da etapa anterior",IF(B10="Número","unidades no mês",""))) -> R$ por lead | E10: =IFERROR(IF(C10="","",IF(B10="Custo",ROUNDUP(ROUND($B$5/C10,6),0),IF(B10="Número",ROUNDUP(ROUND(C10,6),0),""))),"") -> 858 | F10: =IF(AND(ISNUMBER(E10),$B$5>0),IF(B10="Custo",C10,IF(E10>0,$B$5/E10,"")),"") -> 35 | G10: — | H10: =IF(C10="","Preencha o valor",IF(AND(B10="Custo",$B$5<=0),"Informe o investimento previsto",IF(E10="","Confira o valor","")))
A11: Lead em cotação | B11: Porcentagem | C11: 20 | D11: =IF(B11="Custo","R$ por "&LOWER(A11),IF(B11="Porcentagem","% da etapa anterior",IF(B11="Número","unidades no mês",""))) -> % da etapa anterior | E11: =IFERROR(IF(C11="","",IF(B11="Custo",ROUNDUP(ROUND($B$5/C11,6),0),IF(B11="Porcentagem",IF(ISNUMBER(E10),ROUNDUP(ROUND(E10*C11/100,6),0),""),IF(B11="Número",ROUNDUP(ROUND(C11,6),0),"")))),"") -> 172 | F11: =IF(AND(ISNUMBER(E11),$B$5>0),IF(B11="Custo",C11,IF(E11>0,$B$5/E11,"")),"") -> 174.4186 | G11: =IF(AND(ISNUMBER(E11),ISNUMBER(E10)),IF(E10>0,E11/E10,""),"") -> 0.2004662 | H11: =IF(C11="","Preencha o valor",IF(AND(B11="Porcentagem",C11>100),"Porcentagem acima de 100",IF(AND(B11="Porcentagem",NOT(ISNUMBER(E10))),"Defina a etapa anterior",IF(AND(B11="Custo",$B$5<=0),"Informe o investimento previsto",IF(E11="","Confira o valor","")))))
A12: Lead em negociação | B12: Porcentagem | C12: 60 | D12: =IF(B12="Custo","R$ por "&LOWER(A12),IF(B12="Porcentagem","% da etapa anterior",IF(B12="Número","unidades no mês",""))) -> % da etapa anterior | E12: =IFERROR(IF(C12="","",IF(B12="Custo",ROUNDUP(ROUND($B$5/C12,6),0),IF(B12="Porcentagem",IF(ISNUMBER(E11),ROUNDUP(ROUND(E11*C12/100,6),0),""),IF(B12="Número",ROUNDUP(ROUND(C12,6),0),"")))),"") -> 104 | F12: =IF(AND(ISNUMBER(E12),$B$5>0),IF(B12="Custo",C12,IF(E12>0,$B$5/E12,"")),"") -> 288.46154 | G12: =IF(AND(ISNUMBER(E12),ISNUMBER(E11)),IF(E11>0,E12/E11,""),"") -> 0.60465116 | H12: =IF(C12="","Preencha o valor",IF(AND(B12="Porcentagem",C12>100),"Porcentagem acima de 100",IF(AND(B12="Porcentagem",NOT(ISNUMBER(E11))),"Defina a etapa anterior",IF(AND(B12="Custo",$B$5<=0),"Informe o investimento previsto",IF(E12="","Confira o valor","")))))
A13: Venda | B13: Porcentagem | C13: 30 | D13: =IF(B13="Custo","R$ por "&LOWER(A13),IF(B13="Porcentagem","% da etapa anterior",IF(B13="Número","unidades no mês",""))) -> % da etapa anterior | E13: =IFERROR(IF(C13="","",IF(B13="Custo",ROUNDUP(ROUND($B$5/C13,6),0),IF(B13="Porcentagem",IF(ISNUMBER(E12),ROUNDUP(ROUND(E12*C13/100,6),0),""),IF(B13="Número",ROUNDUP(ROUND(C13,6),0),"")))),"") -> 32 | F13: =IF(AND(ISNUMBER(E13),$B$5>0),IF(B13="Custo",C13,IF(E13>0,$B$5/E13,"")),"") -> 937.5 | G13: =IF(AND(ISNUMBER(E13),ISNUMBER(E12)),IF(E12>0,E13/E12,""),"") -> 0.30769231 | H13: =IF(C13="","Preencha o valor",IF(AND(B13="Porcentagem",C13>100),"Porcentagem acima de 100",IF(AND(B13="Porcentagem",NOT(ISNUMBER(E12))),"Defina a etapa anterior",IF(AND(B13="Custo",$B$5<=0),"Informe o investimento previsto",IF(E13="","Confira o valor","")))))
A15: Os números atuais são um exemplo: investimento R$ 30.000, lead a R$ 35,00 (858 leads), cotação em 20% dos leads, negociação em 60% das cotações, venda em 30% das negociações. Troque pelos seus.
A17: Como usar
A18: 1. | B18: Preencha o mês, o investimento previsto e, para cada etapa, escolha "Custo" (R$ por unidade), "Porcentagem" (% da etapa anterior, digite 20 para 20%) ou "Número" (quantidade exata no mês).
A19: 2. | B19: Lead só aceita Custo ou Número: ele é o início do funil, não tem etapa anterior. As demais etapas aceitam os três.
A20: 3. | B20: Pessoas (leads, cotações, negociações, vendas) são sempre números inteiros: o total do mês é arredondado para cima.
A21: 4. | B21: Em "Meta Diária", digite só o REALIZADO de cada dia (células amarelas). As metas de semana e de dia se ajustam sozinhas.
A22: 5. | B22: Compensação: ficou abaixo no dia 1, a meta do dia 2 sobe; ficou abaixo na semana 1, a meta da semana 2 sobe. Dias passados sem lançamento contam como 0; hoje e dias futuros sem lançamento são considerados cumpridos.
A23: 6. | B23: Feriados nacionais já saem como folga (aba Folgas). Acrescente ali feriados locais ou dias sem expediente.
A24: Cores | B24: Azul = valor que você digita · Preto = fórmula · Verde = ligação entre abas · Fundo amarelo = célula para preencher.

Sheet Meta Mensal
A1: ="Meta mensal · "&'Base de Dados'!$B$3 -> Meta mensal · [Nome do cliente]
A3: Mês | B3: ='Base de Dados'!$B$4 -> 46296 | C3: Dias úteis | D3: =Cálculo!B2 -> 21 | E3: Dias encerrados | F3: =Cálculo!B3 -> 7 | G3: Hoje | H3: ='Base de Dados'!$B$6 -> 46308
A5: Métrica | B5: Meta do mês | C5: Realizado | D5: % da meta | E5: Falta | F5: Situação
A6: Investimento (R$) | B6: =IF(ISNUMBER('Base de Dados'!$B$5),'Base de Dados'!$B$5,"") -> 30000 | C6: =IF(COUNT('Meta Diária'!G6:G36)=0,"",SUM('Meta Diária'!G6:G36)) | D6: =IF(AND(ISNUMBER(B6),B6>0,ISNUMBER(C6)),C6/B6,"") | E6: =IF(ISNUMBER(B6),MAX(B6-N(C6),0),"") -> 30000 | F6: =IF(NOT(ISNUMBER(B6)),"—",IF($F$3=0,"Aguardando",IF(N(C6)>=B6*$F$3/$D$3,"No ritmo",IF(N(C6)>=0.7*B6*$F$3/$D$3,"Atenção","Abaixo do ritmo")))) -> Abaixo do ritmo
A7: Lead | B7: =IF(ISNUMBER('Base de Dados'!$E$10),'Base de Dados'!$E$10,"") -> 858 | C7: =IF(COUNT('Meta Diária'!I6:I36)=0,"",SUM('Meta Diária'!I6:I36)) | D7: =IF(AND(ISNUMBER(B7),B7>0,ISNUMBER(C7)),C7/B7,"") | E7: =IF(ISNUMBER(B7),MAX(B7-N(C7),0),"") -> 858 | F7: =IF(NOT(ISNUMBER(B7)),"—",IF($F$3=0,"Aguardando",IF(N(C7)>=B7*$F$3/$D$3,"No ritmo",IF(N(C7)>=0.7*B7*$F$3/$D$3,"Atenção","Abaixo do ritmo")))) -> Abaixo do ritmo
A8: Custo por lead (teto) | B8: =IF(ISNUMBER('Base de Dados'!$F$10),'Base de Dados'!$F$10,"") -> 35 | C8: =IF(AND(COUNT('Meta Diária'!G6:G36)>0,COUNT('Meta Diária'!I6:I36)>0),IF(SUM('Meta Diária'!I6:I36)>0,SUM('Meta Diária'!G6:G36)/SUM('Meta Diária'!I6:I36),""),"") | F8: =IF(NOT(ISNUMBER(B8)),"—",IF(NOT(ISNUMBER(C8)),"Aguardando",IF(C8<=B8,"Dentro do teto",IF(C8<=B8*1.2,"Atenção","Acima do teto")))) -> Aguardando
A9: Lead em cotação | B9: =IF(ISNUMBER('Base de Dados'!$E$11),'Base de Dados'!$E$11,"") -> 172 | C9: =IF(COUNT('Meta Diária'!K6:K36)=0,"",SUM('Meta Diária'!K6:K36)) | D9: =IF(AND(ISNUMBER(B9),B9>0,ISNUMBER(C9)),C9/B9,"") | E9: =IF(ISNUMBER(B9),MAX(B9-N(C9),0),"") -> 172 | F9: =IF(NOT(ISNUMBER(B9)),"—",IF($F$3=0,"Aguardando",IF(N(C9)>=B9*$F$3/$D$3,"No ritmo",IF(N(C9)>=0.7*B9*$F$3/$D$3,"Atenção","Abaixo do ritmo")))) -> Abaixo do ritmo
A10: Custo por cotação (teto) | B10: =IF(ISNUMBER('Base de Dados'!$F$11),'Base de Dados'!$F$11,"") -> 174.4186 | C10: =IF(AND(COUNT('Meta Diária'!G6:G36)>0,COUNT('Meta Diária'!K6:K36)>0),IF(SUM('Meta Diária'!K6:K36)>0,SUM('Meta Diária'!G6:G36)/SUM('Meta Diária'!K6:K36),""),"") | F10: =IF(NOT(ISNUMBER(B10)),"—",IF(NOT(ISNUMBER(C10)),"Aguardando",IF(C10<=B10,"Dentro do teto",IF(C10<=B10*1.2,"Atenção","Acima do teto")))) -> Aguardando
A11: Lead em negociação | B11: =IF(ISNUMBER('Base de Dados'!$E$12),'Base de Dados'!$E$12,"") -> 104 | C11: =IF(COUNT('Meta Diária'!M6:M36)=0,"",SUM('Meta Diária'!M6:M36)) | D11: =IF(AND(ISNUMBER(B11),B11>0,ISNUMBER(C11)),C11/B11,"") | E11: =IF(ISNUMBER(B11),MAX(B11-N(C11),0),"") -> 104 | F11: =IF(NOT(ISNUMBER(B11)),"—",IF($F$3=0,"Aguardando",IF(N(C11)>=B11*$F$3/$D$3,"No ritmo",IF(N(C11)>=0.7*B11*$F$3/$D$3,"Atenção","Abaixo do ritmo")))) -> Abaixo do ritmo
A12: Custo por negociação (teto) | B12: =IF(ISNUMBER('Base de Dados'!$F$12),'Base de Dados'!$F$12,"") -> 288.46154 | C12: =IF(AND(COUNT('Meta Diária'!G6:G36)>0,COUNT('Meta Diária'!M6:M36)>0),IF(SUM('Meta Diária'!M6:M36)>0,SUM('Meta Diária'!G6:G36)/SUM('Meta Diária'!M6:M36),""),"") | F12: =IF(NOT(ISNUMBER(B12)),"—",IF(NOT(ISNUMBER(C12)),"Aguardando",IF(C12<=B12,"Dentro do teto",IF(C12<=B12*1.2,"Atenção","Acima do teto")))) -> Aguardando
A13: Venda | B13: =IF(ISNUMBER('Base de Dados'!$E$13),'Base de Dados'!$E$13,"") -> 32 | C13: =IF(COUNT('Meta Diária'!O6:O36)=0,"",SUM('Meta Diária'!O6:O36)) | D13: =IF(AND(ISNUMBER(B13),B13>0,ISNUMBER(C13)),C13/B13,"") | E13: =IF(ISNUMBER(B13),MAX(B13-N(C13),0),"") -> 32 | F13: =IF(NOT(ISNUMBER(B13)),"—",IF($F$3=0,"Aguardando",IF(N(C13)>=B13*$F$3/$D$3,"No ritmo",IF(N(C13)>=0.7*B13*$F$3/$D$3,"Atenção","Abaixo do ritmo")))) -> Abaixo do ritmo
A14: Custo por venda (teto) | B14: =IF(ISNUMBER('Base de Dados'!$F$13),'Base de Dados'!$F$13,"") -> 937.5 | C14: =IF(AND(COUNT('Meta Diária'!G6:G36)>0,COUNT('Meta Diária'!O6:O36)>0),IF(SUM('Meta Diária'!O6:O36)>0,SUM('Meta Diária'!G6:G36)/SUM('Meta Diária'!O6:O36),""),"") | F14: =IF(NOT(ISNUMBER(B14)),"—",IF(NOT(ISNUMBER(C14)),"Aguardando",IF(C14<=B14,"Dentro do teto",IF(C14<=B14*1.2,"Atenção","Acima do teto")))) -> Aguardando
A16: Meta do mês vem da aba Base de Dados. Custo por unidade (teto) = custo previsto; o realizado é investimento ÷ quantidade lançada. "No ritmo" compara o realizado com a meta proporcional aos dias úteis já encerrados.

Sheet Meta Semanal
A1: ="Meta semanal · "&'Base de Dados'!$B$3 -> Meta semanal · [Nome do cliente]
A2: Semanas de segunda a sexta. A meta de cada semana sobe quando a semana anterior ficou abaixo. O realizado vem da aba Meta Diária.
M4: Teto → | N4: =IF(ISNUMBER('Base de Dados'!$F$10),'Base de Dados'!$F$10,"") -> 35 | O4: =IF(ISNUMBER('Base de Dados'!$F$11),'Base de Dados'!$F$11,"") -> 174.4186 | P4: =IF(ISNUMBER('Base de Dados'!$F$12),'Base de Dados'!$F$12,"") -> 288.46154 | Q4: =IF(ISNUMBER('Base de Dados'!$F$13),'Base de Dados'!$F$13,"") -> 937.5
A5: Semana | B5: Período | C5: Dias úteis | D5: Investimento Meta da semana | E5: Investimento Realizado | F5: Lead Meta da semana | G5: Lead Realizado | H5: Lead em cotação Meta da semana | I5: Lead em cotação Realizado | J5: Lead em negociação Meta da semana | K5: Lead em negociação Realizado | L5: Venda Meta da semana | M5: Venda Realizado | N5: Custo por lead (real) | O5: Custo por cotação (real) | P5: Custo por negociação (real) | Q5: Custo por venda (real)
A6: 1 | B6: =IF(COUNTIF(Cálculo!$B$6:$B$36,$A6)>0,TEXT(_xlfn.MINIFS(Cálculo!$A$6:$A$36,Cálculo!$B$6:$B$36,$A6,Cálculo!$C$6:$C$36,1),"dd/mm")&" a "&TEXT(_xlfn.MAXIFS(Cálculo!$A$6:$A$36,Cálculo!$B$6:$B$36,$A6,Cálculo!$C$6:$C$36,1),"dd/mm"),"") -> 01/10 a 02/10 | C6: =IF(COUNTIF(Cálculo!$B$6:$B$36,$A6)>0,COUNTIFS(Cálculo!$B$6:$B$36,$A6,Cálculo!$C$6:$C$36,1),"") -> 2 | D6: =IF(AND(COUNTIF(Cálculo!$B$6:$B$36,$A6)>0,ISNUMBER('Base de Dados'!$B$5)),INDEX(Cálculo!$M$6:$M$36,MATCH($A6,Cálculo!$B$6:$B$36,0)),"") -> 2857.1429 | E6: =IF(COUNTIF(Cálculo!$B$6:$B$36,$A6)>0,IF(COUNTIFS('Meta Diária'!$C$6:$C$36,$A6,'Meta Diária'!$G$6:$G$36,"<>")=0,"",SUMIFS('Meta Diária'!$G$6:$G$36,'Meta Diária'!$C$6:$C$36,$A6)),"") | F6: =IF(AND(COUNTIF(Cálculo!$B$6:$B$36,$A6)>0,ISNUMBER('Base de Dados'!$E$10)),INDEX(Cálculo!$AE$6:$AE$36,MATCH($A6,Cálculo!$B$6:$B$36,0)),"") -> 82 | G6: =IF(COUNTIF(Cálculo!$B$6:$B$36,$A6)>0,IF(COUNTIFS('Meta Diária'!$C$6:$C$36,$A6,'Meta Diária'!$I$6:$I$36,"<>")=0,"",SUMIFS('Meta Diária'!$I$6:$I$36,'Meta Diária'!$C$6:$C$36,$A6)),"") | H6: =IF(AND(COUNTIF(Cálculo!$B$6:$B$36,$A6)>0,ISNUMBER('Base de Dados'!$E$11)),INDEX(Cálculo!$AX$6:$AX$36,MATCH($A6,Cálculo!$B$6:$B$36,0)),"") -> 16 | I6: =IF(COUNTIF(Cálculo!$B$6:$B$36,$A6)>0,IF(COUNTIFS('Meta Diária'!$C$6:$C$36,$A6,'Meta Diária'!$K$6:$K$36,"<>")=0,"",SUMIFS('Meta Diária'!$K$6:$K$36,'Meta Diária'!$C$6:$C$36,$A6)),"") | J6: =IF(AND(COUNTIF(Cálculo!$B$6:$B$36,$A6)>0,ISNUMBER('Base de Dados'!$E$12)),INDEX(Cálculo!$BQ$6:$BQ$36,MATCH($A6,Cálculo!$B$6:$B$36,0)),"") -> 10 | K6: =IF(COUNTIF(Cálculo!$B$6:$B$36,$A6)>0,IF(COUNTIFS('Meta Diária'!$C$6:$C$36,$A6,'Meta Diária'!$M$6:$M$36,"<>")=0,"",SUMIFS('Meta Diária'!$M$6:$M$36,'Meta Diária'!$C$6:$C$36,$A6)),"") | L6: =IF(AND(COUNTIF(Cálculo!$B$6:$B$36,$A6)>0,ISNUMBER('Base de Dados'!$E$13)),INDEX(Cálculo!$CJ$6:$CJ$36,MATCH($A6,Cálculo!$B$6:$B$36,0)),"") -> 4 | M6: =IF(COUNTIF(Cálculo!$B$6:$B$36,$A6)>0,IF(COUNTIFS('Meta Diária'!$C$6:$C$36,$A6,'Meta Diária'!$O$6:$O$36,"<>")=0,"",SUMIFS('Meta Diária'!$O$6:$O$36,'Meta Diária'!$C$6:$C$36,$A6)),"") | N6: =IF(AND(ISNUMBER(E6),ISNUMBER(G6)),IF(G6>0,E6/G6,""),"") | O6: =IF(AND(ISNUMBER(E6),ISNUMBER(I6)),IF(I6>0,E6/I6,""),"") | P6: =IF(AND(ISNUMBER(E6),ISNUMBER(K6)),IF(K6>0,E6/K6,""),"") | Q6: =IF(AND(ISNUMBER(E6),ISNUMBER(M6)),IF(M6>0,E6/M6,""),"")
A7: 2 | B7: =IF(COUNTIF(Cálculo!$B$6:$B$36,$A7)>0,TEXT(_xlfn.MINIFS(Cálculo!$A$6:$A$36,Cálculo!$B$6:$B$36,$A7,Cálculo!$C$6:$C$36,1),"dd/mm")&" a "&TEXT(_xlfn.MAXIFS(Cálculo!$A$6:$A$36,Cálculo!$B$6:$B$36,$A7,Cálculo!$C$6:$C$36,1),"dd/mm"),"") -> 05/10 a 09/10 | C7: =IF(COUNTIF(Cálculo!$B$6:$B$36,$A7)>0,COUNTIFS(Cálculo!$B$6:$B$36,$A7,Cálculo!$C$6:$C$36,1),"") -> 5 | D7: =IF(AND(COUNTIF(Cálculo!$B$6:$B$36,$A7)>0,ISNUMBER('Base de Dados'!$B$5)),INDEX(Cálculo!$M$6:$M$36,MATCH($A7,Cálculo!$B$6:$B$36,0)),"") -> 7894.7368 | E7: =IF(COUNTIF(Cálculo!$B$6:$B$36,$A7)>0,IF(COUNTIFS('Meta Diária'!$C$6:$C$36,$A7,'Meta Diária'!$G$6:$G$36,"<>")=0,"",SUMIFS('Meta Diária'!$G$6:$G$36,'Meta Diária'!$C$6:$C$36,$A7)),"") | F7: =IF(AND(COUNTIF(Cálculo!$B$6:$B$36,$A7)>0,ISNUMBER('Base de Dados'!$E$10)),INDEX(Cálculo!$AE$6:$AE$36,MATCH($A7,Cálculo!$B$6:$B$36,0)),"") -> 228 | G7: =IF(COUNTIF(Cálculo!$B$6:$B$36,$A7)>0,IF(COUNTIFS('Meta Diária'!$C$6:$C$36,$A7,'Meta Diária'!$I$6:$I$36,"<>")=0,"",SUMIFS('Meta Diária'!$I$6:$I$36,'Meta Diária'!$C$6:$C$36,$A7)),"") | H7: =IF(AND(COUNTIF(Cálculo!$B$6:$B$36,$A7)>0,ISNUMBER('Base de Dados'!$E$11)),INDEX(Cálculo!$AX$6:$AX$36,MATCH($A7,Cálculo!$B$6:$B$36,0)),"") -> 46 | I7: =IF(COUNTIF(Cálculo!$B$6:$B$36,$A7)>0,IF(COUNTIFS('Meta Diária'!$C$6:$C$36,$A7,'Meta Diária'!$K$6:$K$36,"<>")=0,"",SUMIFS('Meta Diária'!$K$6:$K$36,'Meta Diária'!$C$6:$C$36,$A7)),"") | J7: =IF(AND(COUNTIF(Cálculo!$B$6:$B$36,$A7)>0,ISNUMBER('Base de Dados'!$E$12)),INDEX(Cálculo!$BQ$6:$BQ$36,MATCH($A7,Cálculo!$B$6:$B$36,0)),"") -> 30 | K7: =IF(COUNTIF(Cálculo!$B$6:$B$36,$A7)>0,IF(COUNTIFS('Meta Diária'!$C$6:$C$36,$A7,'Meta Diária'!$M$6:$M$36,"<>")=0,"",SUMIFS('Meta Diária'!$M$6:$M$36,'Meta Diária'!$C$6:$C$36,$A7)),"") | L7: =IF(AND(COUNTIF(Cálculo!$B$6:$B$36,$A7)>0,ISNUMBER('Base de Dados'!$E$13)),INDEX(Cálculo!$CJ$6:$CJ$36,MATCH($A7,Cálculo!$B$6:$B$36,0)),"") -> 10 | M7: =IF(COUNTIF(Cálculo!$B$6:$B$36,$A7)>0,IF(COUNTIFS('Meta Diária'!$C$6:$C$36,$A7,'Meta Diária'!$O$6:$O$36,"<>")=0,"",SUMIFS('Meta Diária'!$O$6:$O$36,'Meta Diária'!$C$6:$C$36,$A7)),"") | N7: =IF(AND(ISNUMBER(E7),ISNUMBER(G7)),IF(G7>0,E7/G7,""),"") | O7: =IF(AND(ISNUMBER(E7),ISNUMBER(I7)),IF(I7>0,E7/I7,""),"") | P7: =IF(AND(ISNUMBER(E7),ISNUMBER(K7)),IF(K7>0,E7/K7,""),"") | Q7: =IF(AND(ISNUMBER(E7),ISNUMBER(M7)),IF(M7>0,E7/M7,""),"")
A8: 3 | B8: =IF(COUNTIF(Cálculo!$B$6:$B$36,$A8)>0,TEXT(_xlfn.MINIFS(Cálculo!$A$6:$A$36,Cálculo!$B$6:$B$36,$A8,Cálculo!$C$6:$C$36,1),"dd/mm")&" a "&TEXT(_xlfn.MAXIFS(Cálculo!$A$6:$A$36,Cálculo!$B$6:$B$36,$A8,Cálculo!$C$6:$C$36,1),"dd/mm"),"") -> 13/10 a 16/10 | C8: =IF(COUNTIF(Cálculo!$B$6:$B$36,$A8)>0,COUNTIFS(Cálculo!$B$6:$B$36,$A8,Cálculo!$C$6:$C$36,1),"") -> 4 | D8: =IF(AND(COUNTIF(Cálculo!$B$6:$B$36,$A8)>0,ISNUMBER('Base de Dados'!$B$5)),INDEX(Cálculo!$M$6:$M$36,MATCH($A8,Cálculo!$B$6:$B$36,0)),"") -> 8571.4286 | E8: =IF(COUNTIF(Cálculo!$B$6:$B$36,$A8)>0,IF(COUNTIFS('Meta Diária'!$C$6:$C$36,$A8,'Meta Diária'!$G$6:$G$36,"<>")=0,"",SUMIFS('Meta Diária'!$G$6:$G$36,'Meta Diária'!$C$6:$C$36,$A8)),"") | F8: =IF(AND(COUNTIF(Cálculo!$B$6:$B$36,$A8)>0,ISNUMBER('Base de Dados'!$E$10)),INDEX(Cálculo!$AE$6:$AE$36,MATCH($A8,Cálculo!$B$6:$B$36,0)),"") -> 248 | G8: =IF(COUNTIF(Cálculo!$B$6:$B$36,$A8)>0,IF(COUNTIFS('Meta Diária'!$C$6:$C$36,$A8,'Meta Diária'!$I$6:$I$36,"<>")=0,"",SUMIFS('Meta Diária'!$I$6:$I$36,'Meta Diária'!$C$6:$C$36,$A8)),"") | H8: =IF(AND(COUNTIF(Cálculo!$B$6:$B$36,$A8)>0,ISNUMBER('Base de Dados'!$E$11)),INDEX(Cálculo!$AX$6:$AX$36,MATCH($A8,Cálculo!$B$6:$B$36,0)),"") -> 52 | I8: =IF(COUNTIF(Cálculo!$B$6:$B$36,$A8)>0,IF(COUNTIFS('Meta Diária'!$C$6:$C$36,$A8,'Meta Diária'!$K$6:$K$36,"<>")=0,"",SUMIFS('Meta Diária'!$K$6:$K$36,'Meta Diária'!$C$6:$C$36,$A8)),"") | J8: =IF(AND(COUNTIF(Cálculo!$B$6:$B$36,$A8)>0,ISNUMBER('Base de Dados'!$E$12)),INDEX(Cálculo!$BQ$6:$BQ$36,MATCH($A8,Cálculo!$B$6:$B$36,0)),"") -> 32 | K8: =IF(COUNTIF(Cálculo!$B$6:$B$36,$A8)>0,IF(COUNTIFS('Meta Diária'!$C$6:$C$36,$A8,'Meta Diária'!$M$6:$M$36,"<>")=0,"",SUMIFS('Meta Diária'!$M$6:$M$36,'Meta Diária'!$C$6:$C$36,$A8)),"") | L8: =IF(AND(COUNTIF(Cálculo!$B$6:$B$36,$A8)>0,ISNUMBER('Base de Dados'!$E$13)),INDEX(Cálculo!$CJ$6:$CJ$36,MATCH($A8,Cálculo!$B$6:$B$36,0)),"") -> 12 | M8: =IF(COUNTIF(Cálculo!$B$6:$B$36,$A8)>0,IF(COUNTIFS('Meta Diária'!$C$6:$C$36,$A8,'Meta Diária'!$O$6:$O$36,"<>")=0,"",SUMIFS('Meta Diária'!$O$6:$O$36,'Meta Diária'!$C$6:$C$36,$A8)),"") | N8: =IF(AND(ISNUMBER(E8),ISNUMBER(G8)),IF(G8>0,E8/G8,""),"") | O8: =IF(AND(ISNUMBER(E8),ISNUMBER(I8)),IF(I8>0,E8/I8,""),"") | P8: =IF(AND(ISNUMBER(E8),ISNUMBER(K8)),IF(K8>0,E8/K8,""),"") | Q8: =IF(AND(ISNUMBER(E8),ISNUMBER(M8)),IF(M8>0,E8/M8,""),"")
A9: 4 | B9: =IF(COUNTIF(Cálculo!$B$6:$B$36,$A9)>0,TEXT(_xlfn.MINIFS(Cálculo!$A$6:$A$36,Cálculo!$B$6:$B$36,$A9,Cálculo!$C$6:$C$36,1),"dd/mm")&" a "&TEXT(_xlfn.MAXIFS(Cálculo!$A$6:$A$36,Cálculo!$B$6:$B$36,$A9,Cálculo!$C$6:$C$36,1),"dd/mm"),"") -> 19/10 a 23/10 | C9: =IF(COUNTIF(Cálculo!$B$6:$B$36,$A9)>0,COUNTIFS(Cálculo!$B$6:$B$36,$A9,Cálculo!$C$6:$C$36,1),"") -> 5 | D9: =IF(AND(COUNTIF(Cálculo!$B$6:$B$36,$A9)>0,ISNUMBER('Base de Dados'!$B$5)),INDEX(Cálculo!$M$6:$M$36,MATCH($A9,Cálculo!$B$6:$B$36,0)),"") -> 10714.286 | E9: =IF(COUNTIF(Cálculo!$B$6:$B$36,$A9)>0,IF(COUNTIFS('Meta Diária'!$C$6:$C$36,$A9,'Meta Diária'!$G$6:$G$36,"<>")=0,"",SUMIFS('Meta Diária'!$G$6:$G$36,'Meta Diária'!$C$6:$C$36,$A9)),"") | F9: =IF(AND(COUNTIF(Cálculo!$B$6:$B$36,$A9)>0,ISNUMBER('Base de Dados'!$E$10)),INDEX(Cálculo!$AE$6:$AE$36,MATCH($A9,Cálculo!$B$6:$B$36,0)),"") -> 305 | G9: =IF(COUNTIF(Cálculo!$B$6:$B$36,$A9)>0,IF(COUNTIFS('Meta Diária'!$C$6:$C$36,$A9,'Meta Diária'!$I$6:$I$36,"<>")=0,"",SUMIFS('Meta Diária'!$I$6:$I$36,'Meta Diária'!$C$6:$C$36,$A9)),"") | H9: =IF(AND(COUNTIF(Cálculo!$B$6:$B$36,$A9)>0,ISNUMBER('Base de Dados'!$E$11)),INDEX(Cálculo!$AX$6:$AX$36,MATCH($A9,Cálculo!$B$6:$B$36,0)),"") -> 60 | I9: =IF(COUNTIF(Cálculo!$B$6:$B$36,$A9)>0,IF(COUNTIFS('Meta Diária'!$C$6:$C$36,$A9,'Meta Diária'!$K$6:$K$36,"<>")=0,"",SUMIFS('Meta Diária'!$K$6:$K$36,'Meta Diária'!$C$6:$C$36,$A9)),"") | J9: =IF(AND(COUNTIF(Cálculo!$B$6:$B$36,$A9)>0,ISNUMBER('Base de Dados'!$E$12)),INDEX(Cálculo!$BQ$6:$BQ$36,MATCH($A9,Cálculo!$B$6:$B$36,0)),"") -> 37 | K9: =IF(COUNTIF(Cálculo!$B$6:$B$36,$A9)>0,IF(COUNTIFS('Meta Diária'!$C$6:$C$36,$A9,'Meta Diária'!$M$6:$M$36,"<>")=0,"",SUMIFS('Meta Diária'!$M$6:$M$36,'Meta Diária'!$C$6:$C$36,$A9)),"") | L9: =IF(AND(COUNTIF(Cálculo!$B$6:$B$36,$A9)>0,ISNUMBER('Base de Dados'!$E$13)),INDEX(Cálculo!$CJ$6:$CJ$36,MATCH($A9,Cálculo!$B$6:$B$36,0)),"") -> 10 | M9: =IF(COUNTIF(Cálculo!$B$6:$B$36,$A9)>0,IF(COUNTIFS('Meta Diária'!$C$6:$C$36,$A9,'Meta Diária'!$O$6:$O$36,"<>")=0,"",SUMIFS('Meta Diária'!$O$6:$O$36,'Meta Diária'!$C$6:$C$36,$A9)),"") | N9: =IF(AND(ISNUMBER(E9),ISNUMBER(G9)),IF(G9>0,E9/G9,""),"") | O9: =IF(AND(ISNUMBER(E9),ISNUMBER(I9)),IF(I9>0,E9/I9,""),"") | P9: =IF(AND(ISNUMBER(E9),ISNUMBER(K9)),IF(K9>0,E9/K9,""),"") | Q9: =IF(AND(ISNUMBER(E9),ISNUMBER(M9)),IF(M9>0,E9/M9,""),"")
A10: 5 | B10: =IF(COUNTIF(Cálculo!$B$6:$B$36,$A10)>0,TEXT(_xlfn.MINIFS(Cálculo!$A$6:$A$36,Cálculo!$B$6:$B$36,$A10,Cálculo!$C$6:$C$36,1),"dd/mm")&" a "&TEXT(_xlfn.MAXIFS(Cálculo!$A$6:$A$36,Cálculo!$B$6:$B$36,$A10,Cálculo!$C$6:$C$36,1),"dd/mm"),"") -> 26/10 a 30/10 | C10: =IF(COUNTIF(Cálculo!$B$6:$B$36,$A10)>0,COUNTIFS(Cálculo!$B$6:$B$36,$A10,Cálculo!$C$6:$C$36,1),"") -> 5 | D10: =IF(AND(COUNTIF(Cálculo!$B$6:$B$36,$A10)>0,ISNUMBER('Base de Dados'!$B$5)),INDEX(Cálculo!$M$6:$M$36,MATCH($A10,Cálculo!$B$6:$B$36,0)),"") -> 10714.286 | E10: =IF(COUNTIF(Cálculo!$B$6:$B$36,$A10)>0,IF(COUNTIFS('Meta Diária'!$C$6:$C$36,$A10,'Meta Diária'!$G$6:$G$36,"<>")=0,"",SUMIFS('Meta Diária'!$G$6:$G$36,'Meta Diária'!$C$6:$C$36,$A10)),"") | F10: =IF(AND(COUNTIF(Cálculo!$B$6:$B$36,$A10)>0,ISNUMBER('Base de Dados'!$E$10)),INDEX(Cálculo!$AE$6:$AE$36,MATCH($A10,Cálculo!$B$6:$B$36,0)),"") -> 305 | G10: =IF(COUNTIF(Cálculo!$B$6:$B$36,$A10)>0,IF(COUNTIFS('Meta Diária'!$C$6:$C$36,$A10,'Meta Diária'!$I$6:$I$36,"<>")=0,"",SUMIFS('Meta Diária'!$I$6:$I$36,'Meta Diária'!$C$6:$C$36,$A10)),"") | H10: =IF(AND(COUNTIF(Cálculo!$B$6:$B$36,$A10)>0,ISNUMBER('Base de Dados'!$E$11)),INDEX(Cálculo!$AX$6:$AX$36,MATCH($A10,Cálculo!$B$6:$B$36,0)),"") -> 60 | I10: =IF(COUNTIF(Cálculo!$B$6:$B$36,$A10)>0,IF(COUNTIFS('Meta Diária'!$C$6:$C$36,$A10,'Meta Diária'!$K$6:$K$36,"<>")=0,"",SUMIFS('Meta Diária'!$K$6:$K$36,'Meta Diária'!$C$6:$C$36,$A10)),"") | J10: =IF(AND(COUNTIF(Cálculo!$B$6:$B$36,$A10)>0,ISNUMBER('Base de Dados'!$E$12)),INDEX(Cálculo!$BQ$6:$BQ$36,MATCH($A10,Cálculo!$B$6:$B$36,0)),"") -> 35 | K10: =IF(COUNTIF(Cálculo!$B$6:$B$36,$A10)>0,IF(COUNTIFS('Meta Diária'!$C$6:$C$36,$A10,'Meta Diária'!$M$6:$M$36,"<>")=0,"",SUMIFS('Meta Diária'!$M$6:$M$36,'Meta Diária'!$C$6:$C$36,$A10)),"") | L10: =IF(AND(COUNTIF(Cálculo!$B$6:$B$36,$A10)>0,ISNUMBER('Base de Dados'!$E$13)),INDEX(Cálculo!$CJ$6:$CJ$36,MATCH($A10,Cálculo!$B$6:$B$36,0)),"") -> 10 | M10: =IF(COUNTIF(Cálculo!$B$6:$B$36,$A10)>0,IF(COUNTIFS('Meta Diária'!$C$6:$C$36,$A10,'Meta Diária'!$O$6:$O$36,"<>")=0,"",SUMIFS('Meta Diária'!$O$6:$O$36,'Meta Diária'!$C$6:$C$36,$A10)),"") | N10: =IF(AND(ISNUMBER(E10),ISNUMBER(G10)),IF(G10>0,E10/G10,""),"") | O10: =IF(AND(ISNUMBER(E10),ISNUMBER(I10)),IF(I10>0,E10/I10,""),"") | P10: =IF(AND(ISNUMBER(E10),ISNUMBER(K10)),IF(K10>0,E10/K10,""),"") | Q10: =IF(AND(ISNUMBER(E10),ISNUMBER(M10)),IF(M10>0,E10/M10,""),"")
A11: 6 | B11: =IF(COUNTIF(Cálculo!$B$6:$B$36,$A11)>0,TEXT(_xlfn.MINIFS(Cálculo!$A$6:$A$36,Cálculo!$B$6:$B$36,$A11,Cálculo!$C$6:$C$36,1),"dd/mm")&" a "&TEXT(_xlfn.MAXIFS(Cálculo!$A$6:$A$36,Cálculo!$B$6:$B$36,$A11,Cálculo!$C$6:$C$36,1),"dd/mm"),"") | C11: =IF(COUNTIF(Cálculo!$B$6:$B$36,$A11)>0,COUNTIFS(Cálculo!$B$6:$B$36,$A11,Cálculo!$C$6:$C$36,1),"") | D11: =IF(AND(COUNTIF(Cálculo!$B$6:$B$36,$A11)>0,ISNUMBER('Base de Dados'!$B$5)),INDEX(Cálculo!$M$6:$M$36,MATCH($A11,Cálculo!$B$6:$B$36,0)),"") | E11: =IF(COUNTIF(Cálculo!$B$6:$B$36,$A11)>0,IF(COUNTIFS('Meta Diária'!$C$6:$C$36,$A11,'Meta Diária'!$G$6:$G$36,"<>")=0,"",SUMIFS('Meta Diária'!$G$6:$G$36,'Meta Diária'!$C$6:$C$36,$A11)),"") | F11: =IF(AND(COUNTIF(Cálculo!$B$6:$B$36,$A11)>0,ISNUMBER('Base de Dados'!$E$10)),INDEX(Cálculo!$AE$6:$AE$36,MATCH($A11,Cálculo!$B$6:$B$36,0)),"") | G11: =IF(COUNTIF(Cálculo!$B$6:$B$36,$A11)>0,IF(COUNTIFS('Meta Diária'!$C$6:$C$36,$A11,'Meta Diária'!$I$6:$I$36,"<>")=0,"",SUMIFS('Meta Diária'!$I$6:$I$36,'Meta Diária'!$C$6:$C$36,$A11)),"") | H11: =IF(AND(COUNTIF(Cálculo!$B$6:$B$36,$A11)>0,ISNUMBER('Base de Dados'!$E$11)),INDEX(Cálculo!$AX$6:$AX$36,MATCH($A11,Cálculo!$B$6:$B$36,0)),"") | I11: =IF(COUNTIF(Cálculo!$B$6:$B$36,$A11)>0,IF(COUNTIFS('Meta Diária'!$C$6:$C$36,$A11,'Meta Diária'!$K$6:$K$36,"<>")=0,"",SUMIFS('Meta Diária'!$K$6:$K$36,'Meta Diária'!$C$6:$C$36,$A11)),"") | J11: =IF(AND(COUNTIF(Cálculo!$B$6:$B$36,$A11)>0,ISNUMBER('Base de Dados'!$E$12)),INDEX(Cálculo!$BQ$6:$BQ$36,MATCH($A11,Cálculo!$B$6:$B$36,0)),"") | K11: =IF(COUNTIF(Cálculo!$B$6:$B$36,$A11)>0,IF(COUNTIFS('Meta Diária'!$C$6:$C$36,$A11,'Meta Diária'!$M$6:$M$36,"<>")=0,"",SUMIFS('Meta Diária'!$M$6:$M$36,'Meta Diária'!$C$6:$C$36,$A11)),"") | L11: =IF(AND(COUNTIF(Cálculo!$B$6:$B$36,$A11)>0,ISNUMBER('Base de Dados'!$E$13)),INDEX(Cálculo!$CJ$6:$CJ$36,MATCH($A11,Cálculo!$B$6:$B$36,0)),"") | M11: =IF(COUNTIF(Cálculo!$B$6:$B$36,$A11)>0,IF(COUNTIFS('Meta Diária'!$C$6:$C$36,$A11,'Meta Diária'!$O$6:$O$36,"<>")=0,"",SUMIFS('Meta Diária'!$O$6:$O$36,'Meta Diária'!$C$6:$C$36,$A11)),"") | N11: =IF(AND(ISNUMBER(E11),ISNUMBER(G11)),IF(G11>0,E11/G11,""),"") | O11: =IF(AND(ISNUMBER(E11),ISNUMBER(I11)),IF(I11>0,E11/I11,""),"") | P11: =IF(AND(ISNUMBER(E11),ISNUMBER(K11)),IF(K11>0,E11/K11,""),"") | Q11: =IF(AND(ISNUMBER(E11),ISNUMBER(M11)),IF(M11>0,E11/M11,""),"")
A12: Mês | B12: =TEXT('Base de Dados'!$B$4,"mm/yyyy") -> 10/2026 | C12: =Cálculo!B2 -> 21 | D12: =IF(ISNUMBER('Base de Dados'!$B$5),'Base de Dados'!$B$5,"") -> 30000 | E12: =IF(COUNT(E6:E11)=0,"",SUM(E6:E11)) | F12: =IF(ISNUMBER('Base de Dados'!$E$10),'Base de Dados'!$E$10,"") -> 858 | G12: =IF(COUNT(G6:G11)=0,"",SUM(G6:G11)) | H12: =IF(ISNUMBER('Base de Dados'!$E$11),'Base de Dados'!$E$11,"") -> 172 | I12: =IF(COUNT(I6:I11)=0,"",SUM(I6:I11)) | J12: =IF(ISNUMBER('Base de Dados'!$E$12),'Base de Dados'!$E$12,"") -> 104 | K12: =IF(COUNT(K6:K11)=0,"",SUM(K6:K11)) | L12: =IF(ISNUMBER('Base de Dados'!$E$13),'Base de Dados'!$E$13,"") -> 32 | M12: =IF(COUNT(M6:M11)=0,"",SUM(M6:M11)) | N12: =IF(AND(ISNUMBER(E12),ISNUMBER(G12)),IF(G12>0,E12/G12,""),"") | O12: =IF(AND(ISNUMBER(E12),ISNUMBER(I12)),IF(I12>0,E12/I12,""),"") | P12: =IF(AND(ISNUMBER(E12),ISNUMBER(K12)),IF(K12>0,E12/K12,""),"") | Q12: =IF(AND(ISNUMBER(E12),ISNUMBER(M12)),IF(M12>0,E12/M12,""),"")

Sheet Meta Diária
A1: ="Meta diária (dias úteis) · "&'Base de Dados'!$B$3 -> Meta diária (dias úteis) · [Nome do cliente]
A2: Digite só o REALIZADO de cada dia (células amarelas). A meta de cada dia se ajusta sozinha: ficou abaixo, a meta seguinte sobe.
A3: Verde = bateu a meta do dia · Amarelo = entre 70% e 100% · Vermelho = abaixo de 70% · Custos: verde = dentro do teto, amarelo = até 20% acima, vermelho = acima.
O4: Teto → | P4: =IF(ISNUMBER('Base de Dados'!$F$10),'Base de Dados'!$F$10,"") -> 35 | Q4: =IF(ISNUMBER('Base de Dados'!$F$11),'Base de Dados'!$F$11,"") -> 174.4186 | R4: =IF(ISNUMBER('Base de Dados'!$F$12),'Base de Dados'!$F$12,"") -> 288.46154 | S4: =IF(ISNUMBER('Base de Dados'!$F$13),'Base de Dados'!$F$13,"") -> 937.5
A5: Data | B5: Dia | C5: Semana | D5: Foco do dia | E5: Dia útil? | F5: Investimento Meta do dia | G5: Investimento Realizado | H5: Lead Meta do dia | I5: Lead Realizado | J5: Lead em cotação Meta do dia | K5: Lead em cotação Realizado | L5: Lead em negociação Meta do dia | M5: Lead em negociação Realizado | N5: Venda Meta do dia | O5: Venda Realizado | P5: Custo por lead (real) | Q5: Custo por cotação (real) | R5: Custo por negociação (real) | S5: Custo por venda (real)
A6: =IF(Cálculo!A6="","",Cálculo!A6) -> 46296 | B6: =IF(A6="","",CHOOSE(WEEKDAY(A6,2),"Seg","Ter","Qua","Qui","Sex","Sáb","Dom")) -> Qui | C6: =IF(A6="","",Cálculo!B6) -> 1 | D6: =IF(A6="","",IF(Cálculo!C6=1,CHOOSE(WEEKDAY(A6,2),"Meta da Semana","Foco no Atendimento","Revisão da Semana","Foco no Atendimento","Relatório da Semana"),IF(COUNTIF(Folgas!$A$5:$A$300,A6)>0,"Feriado / folga","Fim de semana"))) -> Foco no Atendimento | E6: =IF(A6="","",IF(Cálculo!C6=1,"Sim","Não")) -> Sim | F6: =IF(OR($E6<>"Sim",NOT(ISNUMBER('Base de Dados'!$B$5))),"",Cálculo!O6) -> 1428.5714 | H6: =IF(OR($E6<>"Sim",NOT(ISNUMBER('Base de Dados'!$E$10))),"",Cálculo!AH6) -> 41 | J6: =IF(OR($E6<>"Sim",NOT(ISNUMBER('Base de Dados'!$E$11))),"",Cálculo!BA6) -> 8 | L6: =IF(OR($E6<>"Sim",NOT(ISNUMBER('Base de Dados'!$E$12))),"",Cálculo!BT6) -> 5 | N6: =IF(OR($E6<>"Sim",NOT(ISNUMBER('Base de Dados'!$E$13))),"",Cálculo!CM6) -> 2 | P6: =IF(AND(ISNUMBER(G6),ISNUMBER(I6)),IF(I6>0,G6/I6,""),"") | Q6: =IF(AND(ISNUMBER(G6),ISNUMBER(K6)),IF(K6>0,G6/K6,""),"") | R6: =IF(AND(ISNUMBER(G6),ISNUMBER(M6)),IF(M6>0,G6/M6,""),"") | S6: =IF(AND(ISNUMBER(G6),ISNUMBER(O6)),IF(O6>0,G6/O6,""),"")
A7: =IF(Cálculo!A7="","",Cálculo!A7) -> 46297 | B7: =IF(A7="","",CHOOSE(WEEKDAY(A7,2),"Seg","Ter","Qua","Qui","Sex","Sáb","Dom")) -> Sex | C7: =IF(A7="","",Cálculo!B7) -> 1 | D7: =IF(A7="","",IF(Cálculo!C7=1,CHOOSE(WEEKDAY(A7,2),"Meta da Semana","Foco no Atendimento","Revisão da Semana","Foco no Atendimento","Relatório da Semana"),IF(COUNTIF(Folgas!$A$5:$A$300,A7)>0,"Feriado / folga","Fim de semana"))) -> Relatório da Semana | E7: =IF(A7="","",IF(Cálculo!C7=1,"Sim","Não")) -> Sim | F7: =IF(OR($E7<>"Sim",NOT(ISNUMBER('Base de Dados'!$B$5))),"",Cálculo!O7) -> 2857.1429 | H7: =IF(OR($E7<>"Sim",NOT(ISNUMBER('Base de Dados'!$E$10))),"",Cálculo!AH7) -> 82 | J7: =IF(OR($E7<>"Sim",NOT(ISNUMBER('Base de Dados'!$E$11))),"",Cálculo!BA7) -> 16 | L7: =IF(OR($E7<>"Sim",NOT(ISNUMBER('Base de Dados'!$E$12))),"",Cálculo!BT7) -> 10 | N7: =IF(OR($E7<>"Sim",NOT(ISNUMBER('Base de Dados'!$E$13))),"",Cálculo!CM7) -> 4 | P7: =IF(AND(ISNUMBER(G7),ISNUMBER(I7)),IF(I7>0,G7/I7,""),"") | Q7: =IF(AND(ISNUMBER(G7),ISNUMBER(K7)),IF(K7>0,G7/K7,""),"") | R7: =IF(AND(ISNUMBER(G7),ISNUMBER(M7)),IF(M7>0,G7/M7,""),"") | S7: =IF(AND(ISNUMBER(G7),ISNUMBER(O7)),IF(O7>0,G7/O7,""),"")
A8: =IF(Cálculo!A8="","",Cálculo!A8) -> 46298 | B8: =IF(A8="","",CHOOSE(WEEKDAY(A8,2),"Seg","Ter","Qua","Qui","Sex","Sáb","Dom")) -> Sáb | C8: =IF(A8="","",Cálculo!B8) -> 1 | D8: =IF(A8="","",IF(Cálculo!C8=1,CHOOSE(WEEKDAY(A8,2),"Meta da Semana","Foco no Atendimento","Revisão da Semana","Foco no Atendimento","Relatório da Semana"),IF(COUNTIF(Folgas!$A$5:$A$300,A8)>0,"Feriado / folga","Fim de semana"))) -> Fim de semana | E8: =IF(A8="","",IF(Cálculo!C8=1,"Sim","Não")) -> Não | F8: =IF(OR($E8<>"Sim",NOT(ISNUMBER('Base de Dados'!$B$5))),"",Cálculo!O8) | H8: =IF(OR($E8<>"Sim",NOT(ISNUMBER('Base de Dados'!$E$10))),"",Cálculo!AH8) | J8: =IF(OR($E8<>"Sim",NOT(ISNUMBER('Base de Dados'!$E$11))),"",Cálculo!BA8) | L8: =IF(OR($E8<>"Sim",NOT(ISNUMBER('Base de Dados'!$E$12))),"",Cálculo!BT8) | N8: =IF(OR($E8<>"Sim",NOT(ISNUMBER('Base de Dados'!$E$13))),"",Cálculo!CM8) | P8: =IF(AND(ISNUMBER(G8),ISNUMBER(I8)),IF(I8>0,G8/I8,""),"") | Q8: =IF(AND(ISNUMBER(G8),ISNUMBER(K8)),IF(K8>0,G8/K8,""),"") | R8: =IF(AND(ISNUMBER(G8),ISNUMBER(M8)),IF(M8>0,G8/M8,""),"") | S8: =IF(AND(ISNUMBER(G8),ISNUMBER(O8)),IF(O8>0,G8/O8,""),"")
A9: =IF(Cálculo!A9="","",Cálculo!A9) -> 46299 | B9: =IF(A9="","",CHOOSE(WEEKDAY(A9,2),"Seg","Ter","Qua","Qui","Sex","Sáb","Dom")) -> Dom | C9: =IF(A9="","",Cálculo!B9) -> 1 | D9: =IF(A9="","",IF(Cálculo!C9=1,CHOOSE(WEEKDAY(A9,2),"Meta da Semana","Foco no Atendimento","Revisão da Semana","Foco no Atendimento","Relatório da Semana"),IF(COUNTIF(Folgas!$A$5:$A$300,A9)>0,"Feriado / folga","Fim de semana"))) -> Fim de semana | E9: =IF(A9="","",IF(Cálculo!C9=1,"Sim","Não")) -> Não | F9: =IF(OR($E9<>"Sim",NOT(ISNUMBER('Base de Dados'!$B$5))),"",Cálculo!O9) | H9: =IF(OR($E9<>"Sim",NOT(ISNUMBER('Base de Dados'!$E$10))),"",Cálculo!AH9) | J9: =IF(OR($E9<>"Sim",NOT(ISNUMBER('Base de Dados'!$E$11))),"",Cálculo!BA9) | L9: =IF(OR($E9<>"Sim",NOT(ISNUMBER('Base de Dados'!$E$12))),"",Cálculo!BT9) | N9: =IF(OR($E9<>"Sim",NOT(ISNUMBER('Base de Dados'!$E$13))),"",Cálculo!CM9) | P9: =IF(AND(ISNUMBER(G9),ISNUMBER(I9)),IF(I9>0,G9/I9,""),"") | Q9: =IF(AND(ISNUMBER(G9),ISNUMBER(K9)),IF(K9>0,G9/K9,""),"") | R9: =IF(AND(ISNUMBER(G9),ISNUMBER(M9)),IF(M9>0,G9/M9,""),"") | S9: =IF(AND(ISNUMBER(G9),ISNUMBER(O9)),IF(O9>0,G9/O9,""),"")
A10: =IF(Cálculo!A10="","",Cálculo!A10) -> 46300 | B10: =IF(A10="","",CHOOSE(WEEKDAY(A10,2),"Seg","Ter","Qua","Qui","Sex","Sáb","Dom")) -> Seg | C10: =IF(A10="","",Cálculo!B10) -> 2 | D10: =IF(A10="","",IF(Cálculo!C10=1,CHOOSE(WEEKDAY(A10,2),"Meta da Semana","Foco no Atendimento","Revisão da Semana","Foco no Atendimento","Relatório da Semana"),IF(COUNTIF(Folgas!$A$5:$A$300,A10)>0,"Feriado / folga","Fim de semana"))) -> Meta da Semana | E10: =IF(A10="","",IF(Cálculo!C10=1,"Sim","Não")) -> Sim | F10: =IF(OR($E10<>"Sim",NOT(ISNUMBER('Base de Dados'!$B$5))),"",Cálculo!O10) -> 1578.9474 | H10: =IF(OR($E10<>"Sim",NOT(ISNUMBER('Base de Dados'!$E$10))),"",Cálculo!AH10) -> 46 | J10: =IF(OR($E10<>"Sim",NOT(ISNUMBER('Base de Dados'!$E$11))),"",Cálculo!BA10) -> 9 | L10: =IF(OR($E10<>"Sim",NOT(ISNUMBER('Base de Dados'!$E$12))),"",Cálculo!BT10) -> 6 | N10: =IF(OR($E10<>"Sim",NOT(ISNUMBER('Base de Dados'!$E$13))),"",Cálculo!CM10) -> 2 | P10: =IF(AND(ISNUMBER(G10),ISNUMBER(I10)),IF(I10>0,G10/I10,""),"") | Q10: =IF(AND(ISNUMBER(G10),ISNUMBER(K10)),IF(K10>0,G10/K10,""),"") | R10: =IF(AND(ISNUMBER(G10),ISNUMBER(M10)),IF(M10>0,G10/M10,""),"") | S10: =IF(AND(ISNUMBER(G10),ISNUMBER(O10)),IF(O10>0,G10/O10,""),"")
A11: =IF(Cálculo!A11="","",Cálculo!A11) -> 46301 | B11: =IF(A11="","",CHOOSE(WEEKDAY(A11,2),"Seg","Ter","Qua","Qui","Sex","Sáb","Dom")) -> Ter | C11: =IF(A11="","",Cálculo!B11) -> 2 | D11: =IF(A11="","",IF(Cálculo!C11=1,CHOOSE(WEEKDAY(A11,2),"Meta da Semana","Foco no Atendimento","Revisão da Semana","Foco no Atendimento","Relatório da Semana"),IF(COUNTIF(Folgas!$A$5:$A$300,A11)>0,"Feriado / folga","Fim de semana"))) -> Foco no Atendimento | E11: =IF(A11="","",IF(Cálculo!C11=1,"Sim","Não")) -> Sim | F11: =IF(OR($E11<>"Sim",NOT(ISNUMBER('Base de Dados'!$B$5))),"",Cálculo!O11) -> 1973.6842 | H11: =IF(OR($E11<>"Sim",NOT(ISNUMBER('Base de Dados'!$E$10))),"",Cálculo!AH11) -> 57 | J11: =IF(OR($E11<>"Sim",NOT(ISNUMBER('Base de Dados'!$E$11))),"",Cálculo!BA11) -> 12 | L11: =IF(OR($E11<>"Sim",NOT(ISNUMBER('Base de Dados'!$E$12))),"",Cálculo!BT11) -> 8 | N11: =IF(OR($E11<>"Sim",NOT(ISNUMBER('Base de Dados'!$E$13))),"",Cálculo!CM11) -> 3 | P11: =IF(AND(ISNUMBER(G11),ISNUMBER(I11)),IF(I11>0,G11/I11,""),"") | Q11: =IF(AND(ISNUMBER(G11),ISNUMBER(K11)),IF(K11>0,G11/K11,""),"") | R11: =IF(AND(ISNUMBER(G11),ISNUMBER(M11)),IF(M11>0,G11/M11,""),"") | S11: =IF(AND(ISNUMBER(G11),ISNUMBER(O11)),IF(O11>0,G11/O11,""),"")
A12: =IF(Cálculo!A12="","",Cálculo!A12) -> 46302 | B12: =IF(A12="","",CHOOSE(WEEKDAY(A12,2),"Seg","Ter","Qua","Qui","Sex","Sáb","Dom")) -> Qua | C12: =IF(A12="","",Cálculo!B12) -> 2 | D12: =IF(A12="","",IF(Cálculo!C12=1,CHOOSE(WEEKDAY(A12,2),"Meta da Semana","Foco no Atendimento","Revisão da Semana","Foco no Atendimento","Relatório da Semana"),IF(COUNTIF(Folgas!$A$5:$A$300,A12)>0,"Feriado / folga","Fim de semana"))) -> Revisão da Semana | E12: =IF(A12="","",IF(Cálculo!C12=1,"Sim","Não")) -> Sim | F12: =IF(OR($E12<>"Sim",NOT(ISNUMBER('Base de Dados'!$B$5))),"",Cálculo!O12) -> 2631.5789 | H12: =IF(OR($E12<>"Sim",NOT(ISNUMBER('Base de Dados'!$E$10))),"",Cálculo!AH12) -> 76 | J12: =IF(OR($E12<>"Sim",NOT(ISNUMBER('Base de Dados'!$E$11))),"",Cálculo!BA12) -> 16 | L12: =IF(OR($E12<>"Sim",NOT(ISNUMBER('Base de Dados'!$E$12))),"",Cálculo!BT12) -> 10 | N12: =IF(OR($E12<>"Sim",NOT(ISNUMBER('Base de Dados'!$E$13))),"",Cálculo!CM12) -> 4 | P12: =IF(AND(ISNUMBER(G12),ISNUMBER(I12)),IF(I12>0,G12/I12,""),"") | Q12: =IF(AND(ISNUMBER(G12),ISNUMBER(K12)),IF(K12>0,G12/K12,""),"") | R12: =IF(AND(ISNUMBER(G12),ISNUMBER(M12)),IF(M12>0,G12/M12,""),"") | S12: =IF(AND(ISNUMBER(G12),ISNUMBER(O12)),IF(O12>0,G12/O12,""),"")
A13: =IF(Cálculo!A13="","",Cálculo!A13) -> 46303 | B13: =IF(A13="","",CHOOSE(WEEKDAY(A13,2),"Seg","Ter","Qua","Qui","Sex","Sáb","Dom")) -> Qui | C13: =IF(A13="","",Cálculo!B13) -> 2 | D13: =IF(A13="","",IF(Cálculo!C13=1,CHOOSE(WEEKDAY(A13,2),"Meta da Semana","Foco no Atendimento","Revisão da Semana","Foco no Atendimento","Relatório da Semana"),IF(COUNTIF(Folgas!$A$5:$A$300,A13)>0,"Feriado / folga","Fim de semana"))) -> Foco no Atendimento | E13: =IF(A13="","",IF(Cálculo!C13=1,"Sim","Não")) -> Sim | F13: =IF(OR($E13<>"Sim",NOT(ISNUMBER('Base de Dados'!$B$5))),"",Cálculo!O13) -> 3947.3684 | H13: =IF(OR($E13<>"Sim",NOT(ISNUMBER('Base de Dados'!$E$10))),"",Cálculo!AH13) -> 114 | J13: =IF(OR($E13<>"Sim",NOT(ISNUMBER('Base de Dados'!$E$11))),"",Cálculo!BA13) -> 23 | L13: =IF(OR($E13<>"Sim",NOT(ISNUMBER('Base de Dados'!$E$12))),"",Cálculo!BT13) -> 15 | N13: =IF(OR($E13<>"Sim",NOT(ISNUMBER('Base de Dados'!$E$13))),"",Cálculo!CM13) -> 5 | P13: =IF(AND(ISNUMBER(G13),ISNUMBER(I13)),IF(I13>0,G13/I13,""),"") | Q13: =IF(AND(ISNUMBER(G13),ISNUMBER(K13)),IF(K13>0,G13/K13,""),"") | R13: =IF(AND(ISNUMBER(G13),ISNUMBER(M13)),IF(M13>0,G13/M13,""),"") | S13: =IF(AND(ISNUMBER(G13),ISNUMBER(O13)),IF(O13>0,G13/O13,""),"")
A14: =IF(Cálculo!A14="","",Cálculo!A14) -> 46304 | B14: =IF(A14="","",CHOOSE(WEEKDAY(A14,2),"Seg","Ter","Qua","Qui","Sex","Sáb","Dom")) -> Sex | C14: =IF(A14="","",Cálculo!B14) -> 2 | D14: =IF(A14="","",IF(Cálculo!C14=1,CHOOSE(WEEKDAY(A14,2),"Meta da Semana","Foco no Atendimento","Revisão da Semana","Foco no Atendimento","Relatório da Semana"),IF(COUNTIF(Folgas!$A$5:$A$300,A14)>0,"Feriado / folga","Fim de semana"))) -> Relatório da Semana | E14: =IF(A14="","",IF(Cálculo!C14=1,"Sim","Não")) -> Sim | F14: =IF(OR($E14<>"Sim",NOT(ISNUMBER('Base de Dados'!$B$5))),"",Cálculo!O14) -> 7894.7368 | H14: =IF(OR($E14<>"Sim",NOT(ISNUMBER('Base de Dados'!$E$10))),"",Cálculo!AH14) -> 228 | J14: =IF(OR($E14<>"Sim",NOT(ISNUMBER('Base de Dados'!$E$11))),"",Cálculo!BA14) -> 46 | L14: =IF(OR($E14<>"Sim",NOT(ISNUMBER('Base de Dados'!$E$12))),"",Cálculo!BT14) -> 30 | N14: =IF(OR($E14<>"Sim",NOT(ISNUMBER('Base de Dados'!$E$13))),"",Cálculo!CM14) -> 10 | P14: =IF(AND(ISNUMBER(G14),ISNUMBER(I14)),IF(I14>0,G14/I14,""),"") | Q14: =IF(AND(ISNUMBER(G14),ISNUMBER(K14)),IF(K14>0,G14/K14,""),"") | R14: =IF(AND(ISNUMBER(G14),ISNUMBER(M14)),IF(M14>0,G14/M14,""),"") | S14: =IF(AND(ISNUMBER(G14),ISNUMBER(O14)),IF(O14>0,G14/O14,""),"")
A15: =IF(Cálculo!A15="","",Cálculo!A15) -> 46305 | B15: =IF(A15="","",CHOOSE(WEEKDAY(A15,2),"Seg","Ter","Qua","Qui","Sex","Sáb","Dom")) -> Sáb | C15: =IF(A15="","",Cálculo!B15) -> 2 | D15: =IF(A15="","",IF(Cálculo!C15=1,CHOOSE(WEEKDAY(A15,2),"Meta da Semana","Foco no Atendimento","Revisão da Semana","Foco no Atendimento","Relatório da Semana"),IF(COUNTIF(Folgas!$A$5:$A$300,A15)>0,"Feriado / folga","Fim de semana"))) -> Fim de semana | E15: =IF(A15="","",IF(Cálculo!C15=1,"Sim","Não")) -> Não | F15: =IF(OR($E15<>"Sim",NOT(ISNUMBER('Base de Dados'!$B$5))),"",Cálculo!O15) | H15: =IF(OR($E15<>"Sim",NOT(ISNUMBER('Base de Dados'!$E$10))),"",Cálculo!AH15) | J15: =IF(OR($E15<>"Sim",NOT(ISNUMBER('Base de Dados'!$E$11))),"",Cálculo!BA15) | L15: =IF(OR($E15<>"Sim",NOT(ISNUMBER('Base de Dados'!$E$12))),"",Cálculo!BT15) | N15: =IF(OR($E15<>"Sim",NOT(ISNUMBER('Base de Dados'!$E$13))),"",Cálculo!CM15) | P15: =IF(AND(ISNUMBER(G15),ISNUMBER(I15)),IF(I15>0,G15/I15,""),"") | Q15: =IF(AND(ISNUMBER(G15),ISNUMBER(K15)),IF(K15>0,G15/K15,""),"") | R15: =IF(AND(ISNUMBER(G15),ISNUMBER(M15)),IF(M15>0,G15/M15,""),"") | S15: =IF(AND(ISNUMBER(G15),ISNUMBER(O15)),IF(O15>0,G15/O15,""),"")
A16: =IF(Cálculo!A16="","",Cálculo!A16) -> 46306 | B16: =IF(A16="","",CHOOSE(WEEKDAY(A16,2),"Seg","Ter","Qua","Qui","Sex","Sáb","Dom")) -> Dom | C16: =IF(A16="","",Cálculo!B16) -> 2 | D16: =IF(A16="","",IF(Cálculo!C16=1,CHOOSE(WEEKDAY(A16,2),"Meta da Semana","Foco no Atendimento","Revisão da Semana","Foco no Atendimento","Relatório da Semana"),IF(COUNTIF(Folgas!$A$5:$A$300,A16)>0,"Feriado / folga","Fim de semana"))) -> Fim de semana | E16: =IF(A16="","",IF(Cálculo!C16=1,"Sim","Não")) -> Não | F16: =IF(OR($E16<>"Sim",NOT(ISNUMBER('Base de Dados'!$B$5))),"",Cálculo!O16) | H16: =IF(OR($E16<>"Sim",NOT(ISNUMBER('Base de Dados'!$E$10))),"",Cálculo!AH16) | J16: =IF(OR($E16<>"Sim",NOT(ISNUMBER('Base de Dados'!$E$11))),"",Cálculo!BA16) | L16: =IF(OR($E16<>"Sim",NOT(ISNUMBER('Base de Dados'!$E$12))),"",Cálculo!BT16) | N16: =IF(OR($E16<>"Sim",NOT(ISNUMBER('Base de Dados'!$E$13))),"",Cálculo!CM16) | P16: =IF(AND(ISNUMBER(G16),ISNUMBER(I16)),IF(I16>0,G16/I16,""),"") | Q16: =IF(AND(ISNUMBER(G16),ISNUMBER(K16)),IF(K16>0,G16/K16,""),"") | R16: =IF(AND(ISNUMBER(G16),ISNUMBER(M16)),IF(M16>0,G16/M16,""),"") | S16: =IF(AND(ISNUMBER(G16),ISNUMBER(O16)),IF(O16>0,G16/O16,""),"")
A17: =IF(Cálculo!A17="","",Cálculo!A17) -> 46307 | B17: =IF(A17="","",CHOOSE(WEEKDAY(A17,2),"Seg","Ter","Qua","Qui","Sex","Sáb","Dom")) -> Seg | C17: =IF(A17="","",Cálculo!B17) -> 3 | D17: =IF(A17="","",IF(Cálculo!C17=1,CHOOSE(WEEKDAY(A17,2),"Meta da Semana","Foco no Atendimento","Revisão da Semana","Foco no Atendimento","Relatório da Semana"),IF(COUNTIF(Folgas!$A$5:$A$300,A17)>0,"Feriado / folga","Fim de semana"))) -> Feriado / folga | E17: =IF(A17="","",IF(Cálculo!C17=1,"Sim","Não")) -> Não | F17: =IF(OR($E17<>"Sim",NOT(ISNUMBER('Base de Dados'!$B$5))),"",Cálculo!O17) | H17: =IF(OR($E17<>"Sim",NOT(ISNUMBER('Base de Dados'!$E$10))),"",Cálculo!AH17) | J17: =IF(OR($E17<>"Sim",NOT(ISNUMBER('Base de Dados'!$E$11))),"",Cálculo!BA17) | L17: =IF(OR($E17<>"Sim",NOT(ISNUMBER('Base de Dados'!$E$12))),"",Cálculo!BT17) | N17: =IF(OR($E17<>"Sim",NOT(ISNUMBER('Base de Dados'!$E$13))),"",Cálculo!CM17) | P17: =IF(AND(ISNUMBER(G17),ISNUMBER(I17)),IF(I17>0,G17/I17,""),"") | Q17: =IF(AND(ISNUMBER(G17),ISNUMBER(K17)),IF(K17>0,G17/K17,""),"") | R17: =IF(AND(ISNUMBER(G17),ISNUMBER(M17)),IF(M17>0,G17/M17,""),"") | S17: =IF(AND(ISNUMBER(G17),ISNUMBER(O17)),IF(O17>0,G17/O17,""),"")
... A36: =IF(Cálculo!A36="","",Cálculo!A36) -> 46326 | B36: =IF(A36="","",CHOOSE(WEEKDAY(A36,2),"Seg","Ter","Qua","Qui","Sex","Sáb","Dom")) -> Sáb | C36: =IF(A36="","",Cálculo!B36) -> 5 | D36: =IF(A36="","",IF(Cálculo!C36=1,CHOOSE(WEEKDAY(A36,2),"Meta da Semana","Foco no Atendimento","Revisão da Semana","Foco no Atendimento","Relatório da Semana"),IF(COUNTIF(Folgas!$A$5:$A$300,A36)>0,"Feriado / folga","Fim de semana"))) -> Fim de semana | E36: =IF(A36="","",IF(Cálculo!C36=1,"Sim","Não")) -> Não | F36: =IF(OR($E36<>"Sim",NOT(ISNUMBER('Base de Dados'!$B$5))),"",Cálculo!O36) | H36: =IF(OR($E36<>"Sim",NOT(ISNUMBER('Base de Dados'!$E$10))),"",Cálculo!AH36) | J36: =IF(OR($E36<>"Sim",NOT(ISNUMBER('Base de Dados'!$E$11))),"",Cálculo!BA36) | L36: =IF(OR($E36<>"Sim",NOT(ISNUMBER('Base de Dados'!$E$12))),"",Cálculo!BT36) | N36: =IF(OR($E36<>"Sim",NOT(ISNUMBER('Base de Dados'!$E$13))),"",Cálculo!CM36) | P36: =IF(AND(ISNUMBER(G36),ISNUMBER(I36)),IF(I36>0,G36/I36,""),"") | Q36: =IF(AND(ISNUMBER(G36),ISNUMBER(K36)),IF(K36>0,G36/K36,""),"") | R36: =IF(AND(ISNUMBER(G36),ISNUMBER(M36)),IF(M36>0,G36/M36,""),"") | S36: =IF(AND(ISNUMBER(G36),ISNUMBER(O36)),IF(O36>0,G36/O36,""),"")
A37: Total do mês | G37: =IF(COUNT(G6:G36)=0,"",SUM(G6:G36)) | I37: =IF(COUNT(I6:I36)=0,"",SUM(I6:I36)) | K37: =IF(COUNT(K6:K36)=0,"",SUM(K6:K36)) | M37: =IF(COUNT(M6:M36)=0,"",SUM(M6:M36)) | O37: =IF(COUNT(O6:O36)=0,"",SUM(O6:O36)) | P37: =IF(AND(ISNUMBER(G37),ISNUMBER(I37)),IF(I37>0,G37/I37,""),"") | Q37: =IF(AND(ISNUMBER(G37),ISNUMBER(K37)),IF(K37>0,G37/K37,""),"") | R37: =IF(AND(ISNUMBER(G37),ISNUMBER(M37)),IF(M37>0,G37/M37,""),"") | S37: =IF(AND(ISNUMBER(G37),ISNUMBER(O37)),IF(O37>0,G37/O37,""),"")

Sheet Cálculo
A1: Cálculo — motor das metas (não precisa mexer)
A2: Dias úteis do mês (N) | B2: =SUM(C6:C36) -> 21 | D2: Primeiro dia do mês | E2: =DATE(YEAR('Base de Dados'!$B$4),MONTH('Base de Dados'!$B$4),1) -> 46296 | J2: Total do mês — Investimento | P2: Total do mês — Lead | AI2: Total do mês — Lead em cotação | BB2: Total do mês — Lead em negociação | BU2: Total do mês — Venda
A3: Dias úteis já encerrados | B3: =COUNTIFS(C6:C36,1,A6:A36,"<"&'Base de Dados'!$B$6) -> 7 | D3: Segunda-feira da 1ª semana | E3: =E2-WEEKDAY(E2,2)+1 -> 46293 | J3: =N('Base de Dados'!$B$5) -> 30000 | P3: =N('Base de Dados'!$E$10) -> 858 | AI3: =N('Base de Dados'!$E$11) -> 172 | BB3: =N('Base de Dados'!$E$12) -> 104 | BU3: =N('Base de Dados'!$E$13) -> 32
A5: Data | B5: Semana | C5: Útil (1/0) | D5: Nº do dia útil na semana | E5: Dias úteis na semana | F5: Dias úteis do mês a partir da semana | G5: Início de semana | H5: Semana do calendário (seg-dom) | J5: Investimento: projetado do dia | K5: Projetado até o dia anterior | L5: Meta-base da semana | M5: Meta da semana | N5: Meta-base do dia | O5: Meta do dia | P5: Lead: projetado do dia | Q5: Projetado até o dia anterior | R5: Semana atrasada? (1/0) | S5: Metas-base das semanas anteriores | T5: Parte 1 da semana | U5: Parte 2 da semana | V5: Parte 3 da semana | W5: Parte 4 da semana | X5: Parte 5 da semana | Y5: Parte-base 1 da semana | Z5: Parte-base 2 da semana | AA5: Parte-base 3 da semana | AB5: Parte-base 4 da semana | AC5: Parte-base 5 da semana | AD5: Meta-base da semana | AE5: Meta da semana | AF5: Restante base (dias) | AG5: Meta-base do dia | AH5: Meta do dia | AI5: Lead em cotação: projetado do dia | AJ5: Projetado até o dia anterior | AK5: Semana atrasada? (1/0) | AL5: Metas-base das semanas anteriores | AM5: Parte 1 da semana | AN5: Parte 2 da semana | AO5: Parte 3 da semana | AP5: Parte 4 da semana | AQ5: Parte 5 da semana | AR5: Parte-base 1 da semana | AS5: Parte-base 2 da semana | AT5: Parte-base 3 da semana | AU5: Parte-base 4 da semana | AV5: Parte-base 5 da semana | AW5: Meta-base da semana | AX5: Meta da semana | AY5: Restante base (dias) | AZ5: Meta-base do dia | BA5: Meta do dia | BB5: Lead em negociação: projetado do dia | BC5: Projetado até o dia anterior | BD5: Semana atrasada? (1/0) | BE5: Metas-base das semanas anteriores | BF5: Parte 1 da semana | BG5: Parte 2 da semana | BH5: Parte 3 da semana | BI5: Parte 4 da semana | BJ5: Parte 5 da semana | BK5: Parte-base 1 da semana | BL5: Parte-base 2 da semana | BM5: Parte-base 3 da semana | BN5: Parte-base 4 da semana | BO5: Parte-base 5 da semana | BP5: Meta-base da semana | BQ5: Meta da semana | BR5: Restante base (dias) | BS5: Meta-base do dia | BT5: Meta do dia | BU5: Venda: projetado do dia | BV5: Projetado até o dia anterior | BW5: Semana atrasada? (1/0) | BX5: Metas-base das semanas anteriores | BY5: Parte 1 da semana | BZ5: Parte 2 da semana | CA5: Parte 3 da semana | CB5: Parte 4 da semana | CC5: Parte 5 da semana | CD5: Parte-base 1 da semana | CE5: Parte-base 2 da semana | CF5: Parte-base 3 da semana | CG5: Parte-base 4 da semana | CH5: Parte-base 5 da semana | CI5: Meta-base da semana | CJ5: Meta da semana | CK5: Restante base (dias) | CL5: Meta-base do dia | CM5: Meta do dia
A6: =IF($E$2+0<=EOMONTH($E$2,0),$E$2+0,"") -> 46296 | B6: =IF(A6="","",IF(COUNTIFS(H$6:H$36,H6,C$6:C$36,1)=0,"",IF(H6=H5,B5,1+MAX(B$5:B5)))) -> 1 | C6: =IF(A6="",0,IF(AND(WEEKDAY(A6,2)<=5,COUNTIF(Folgas!$A$5:$A$300,A6)=0),1,0)) -> 1 | D6: =IF(C6=1,COUNTIFS(B$6:B6,B6,C$6:C6,1),0) -> 1 | E6: =IF(OR(A6="",B6=""),0,COUNTIFS(B$6:B$36,B6,C$6:C$36,1)) -> 2 | F6: =IF(OR(A6="",B6=""),0,COUNTIFS(B$6:B$36,">="&B6,C$6:C$36,1)) -> 21 | G6: =IF(OR(A6="",B6=""),0,IF(B6=B5,0,1)) -> 1 | H6: =IF(A6="","",INT((A6-$E$3)/7)+1) -> 1 | J6: =IF($A6="",0,IF('Meta Diária'!G6<>"",'Meta Diária'!G6,IF(AND($C6=1,$A6>='Base de Dados'!$B$6),O6,0))) -> 0 | K6: 0 | L6: =IF($A6="","",IF($G6=1,IF($B$2=0,0,$J$3*$E6/$B$2),L5)) -> 2857.1429 | M6: =IF($A6="","",IF($G6=1,IF('Base de Dados'!$B$7="Sim",IF($F6=0,0,MAX($J$3-K6,0)*$E6/$F6),MAX(L6,IF($F6=0,0,MAX($J$3-K6,0)*$E6/$F6))),M5)) -> 2857.1429 | N6: =IF($C6=1,M6/$E6,"") -> 1428.5714 | O6: =IF($C6<>1,"",IF('Base de Dados'!$B$7="Sim",MAX(M6-SUMIFS(J$5:J5,$B$5:$B5,$B6),0)/($E6-$D6+1),MAX(N6,MAX(M6-SUMIFS(J$5:J5,$B$5:$B5,$B6),0)/($E6-$D6+1)))) -> 1428.5714 | P6: =IF($A6="",0,IF('Meta Diária'!I6<>"",'Meta Diária'!I6,IF(AND($C6=1,$A6>='Base de Dados'!$B$6),AH6,0))) -> 0 | Q6: 0 | R6: =IF($G6=1,IF(Q6<S6-0.000000001,1,0),"") -> 0 | S6: =IF($G6=1,SUMIFS(AD$5:AD5,$G$5:$G5,1),"") -> 0 | T6: =IF($G6=1,IF(AND($E6>=1,($F6-0)>0),IF(R6=1,ROUNDUP(ROUND((MAX($P$3-Q6,0)-(0))/($F6-0),6),0),ROUND((MAX($P$3-Q6,0)-(0))/($F6-0),0)),0),"") -> 41 | U6: =IF($G6=1,IF(AND($E6>=2,($F6-1)>0),IF(R6=1,ROUNDUP(ROUND((MAX($P$3-Q6,0)-(T6))/($F6-1),6),0),ROUND((MAX($P$3-Q6,0)-(T6))/($F6-1),0)),0),"") -> 41 | V6: =IF($G6=1,IF(AND($E6>=3,($F6-2)>0),IF(R6=1,ROUNDUP(ROUND((MAX($P$3-Q6,0)-(T6+U6))/($F6-2),6),0),ROUND((MAX($P$3-Q6,0)-(T6+U6))/($F6-2),0)),0),"") -> 0 | W6: =IF($G6=1,IF(AND($E6>=4,($F6-3)>0),IF(R6=1,ROUNDUP(ROUND((MAX($P$3-Q6,0)-(T6+U6+V6))/($F6-3),6),0),ROUND((MAX($P$3-Q6,0)-(T6+U6+V6))/($F6-3),0)),0),"") -> 0 | X6: =IF($G6=1,IF(AND($E6>=5,($F6-4)>0),IF(R6=1,ROUNDUP(ROUND((MAX($P$3-Q6,0)-(T6+U6+V6+W6))/($F6-4),6),0),ROUND((MAX($P$3-Q6,0)-(T6+U6+V6+W6))/($F6-4),0)),0),"") -> 0 | Y6: =IF($G6=1,IF(AND($E6>=1,($F6-0)>0),ROUND((($P$3-S6)-(0))/($F6-0),0),0),"") -> 41 | Z6: =IF($G6=1,IF(AND($E6>=2,($F6-1)>0),ROUND((($P$3-S6)-(Y6))/($F6-1),0),0),"") -> 41 | AA6: =IF($G6=1,IF(AND($E6>=3,($F6-2)>0),ROUND((($P$3-S6)-(Y6+Z6))/($F6-2),0),0),"") -> 0 | AB6: =IF($G6=1,IF(AND($E6>=4,($F6-3)>0),ROUND((($P$3-S6)-(Y6+Z6+AA6))/($F6-3),0),0),"") -> 0 | AC6: =IF($G6=1,IF(AND($E6>=5,($F6-4)>0),ROUND((($P$3-S6)-(Y6+Z6+AA6+AB6))/($F6-4),0),0),"") -> 0 | AD6: =IF($A6="","",IF($G6=1,(Y6+Z6+AA6+AB6+AC6),AD5)) -> 82 | AE6: =IF($A6="","",IF($G6=1,IF('Base de Dados'!$B$7="Sim",(T6+U6+V6+W6+X6),MAX(AD6,(T6+U6+V6+W6+X6))),AE5)) -> 82 | AF6: =IF($A6="","",IF($G6=1,AD6,AF5-N(AG5))) -> 82 | AG6: =IF($C6=1,ROUND(AF6/($E6-$D6+1),0),"") -> 41 | AH6: =IF($C6<>1,"",IF('Base de Dados'!$B$7="Sim",IF(SUMIFS(P$5:P5,$B$5:$B5,$B6)<SUMIFS(AG$5:AG5,$B$5:$B5,$B6)-0.000000001,ROUNDUP(ROUND(MAX(AE6-SUMIFS(P$5:P5,$B$5:$B5,$B6),0)/($E6-$D6+1),6),0),ROUND(MAX(AE6-SUMIFS(P$5:P5,$B$5:$B5,$B6),0)/($E6-$D6+1),0)),MAX(AG6,IF(SUMIFS(P$5:P5,$B$5:$B5,$B6)<SUMIFS(AG$5:AG5,$B$5:$B5,$B6)-0.000000001,ROUNDUP(ROUND(MAX(AE6-SUMIFS(P$5:P5,$B$5:$B5,$B6),0)/($E6-$D6+1),6),0),ROUND(MAX(AE6-SUMIFS(P$5:P5,$B$5:$B5,$B6),0)/($E6-$D6+1),0))))) -> 41 | AI6: =IF($A6="",0,IF('Meta Diária'!K6<>"",'Meta Diária'!K6,IF(AND($C6=1,$A6>='Base de Dados'!$B$6),BA6,0))) -> 0 | AJ6: 0 | AK6: =IF($G6=1,IF(AJ6<AL6-0.000000001,1,0),"") -> 0 | AL6: =IF($G6=1,SUMIFS(AW$5:AW5,$G$5:$G5,1),"") -> 0 | AM6: =IF($G6=1,IF(AND($E6>=1,($F6-0)>0),IF(AK6=1,ROUNDUP(ROUND((MAX($AI$3-AJ6,0)-(0))/($F6-0),6),0),ROUND((MAX($AI$3-AJ6,0)-(0))/($F6-0),0)),0),"") -> 8 | AN6: =IF($G6=1,IF(AND($E6>=2,($F6-1)>0),IF(AK6=1,ROUNDUP(ROUND((MAX($AI$3-AJ6,0)-(AM6))/($F6-1),6),0),ROUND((MAX($AI$3-AJ6,0)-(AM6))/($F6-1),0)),0),"") -> 8 | AO6: =IF($G6=1,IF(AND($E6>=3,($F6-2)>0),IF(AK6=1,ROUNDUP(ROUND((MAX($AI$3-AJ6,0)-(AM6+AN6))/($F6-2),6),0),ROUND((MAX($AI$3-AJ6,0)-(AM6+AN6))/($F6-2),0)),0),"") -> 0 | AP6: =IF($G6=1,IF(AND($E6>=4,($F6-3)>0),IF(AK6=1,ROUNDUP(ROUND((MAX($AI$3-AJ6,0)-(AM6+AN6+AO6))/($F6-3),6),0),ROUND((MAX($AI$3-AJ6,0)-(AM6+AN6+AO6))/($F6-3),0)),0),"") -> 0 | AQ6: =IF($G6=1,IF(AND($E6>=5,($F6-4)>0),IF(AK6=1,ROUNDUP(ROUND((MAX($AI$3-AJ6,0)-(AM6+AN6+AO6+AP6))/($F6-4),6),0),ROUND((MAX($AI$3-AJ6,0)-(AM6+AN6+AO6+AP6))/($F6-4),0)),0),"") -> 0 | AR6: =IF($G6=1,IF(AND($E6>=1,($F6-0)>0),ROUND((($AI$3-AL6)-(0))/($F6-0),0),0),"") -> 8 | AS6: =IF($G6=1,IF(AND($E6>=2,($F6-1)>0),ROUND((($AI$3-AL6)-(AR6))/($F6-1),0),0),"") -> 8 | AT6: =IF($G6=1,IF(AND($E6>=3,($F6-2)>0),ROUND((($AI$3-AL6)-(AR6+AS6))/($F6-2),0),0),"") -> 0 | AU6: =IF($G6=1,IF(AND($E6>=4,($F6-3)>0),ROUND((($AI$3-AL6)-(AR6+AS6+AT6))/($F6-3),0),0),"") -> 0 | AV6: =IF($G6=1,IF(AND($E6>=5,($F6-4)>0),ROUND((($AI$3-AL6)-(AR6+AS6+AT6+AU6))/($F6-4),0),0),"") -> 0 | AW6: =IF($A6="","",IF($G6=1,(AR6+AS6+AT6+AU6+AV6),AW5)) -> 16 | AX6: =IF($A6="","",IF($G6=1,IF('Base de Dados'!$B$7="Sim",(AM6+AN6+AO6+AP6+AQ6),MAX(AW6,(AM6+AN6+AO6+AP6+AQ6))),AX5)) -> 16 | AY6: =IF($A6="","",IF($G6=1,AW6,AY5-N(AZ5))) -> 16 | AZ6: =IF($C6=1,ROUND(AY6/($E6-$D6+1),0),"") -> 8 | BA6: =IF($C6<>1,"",IF('Base de Dados'!$B$7="Sim",IF(SUMIFS(AI$5:AI5,$B$5:$B5,$B6)<SUMIFS(AZ$5:AZ5,$B$5:$B5,$B6)-0.000000001,ROUNDUP(ROUND(MAX(AX6-SUMIFS(AI$5:AI5,$B$5:$B5,$B6),0)/($E6-$D6+1),6),0),ROUND(MAX(AX6-SUMIFS(AI$5:AI5,$B$5:$B5,$B6),0)/($E6-$D6+1),0)),MAX(AZ6,IF(SUMIFS(AI$5:AI5,$B$5:$B5,$B6)<SUMIFS(AZ$5:AZ5,$B$5:$B5,$B6)-0.000000001,ROUNDUP(ROUND(MAX(AX6-SUMIFS(AI$5:AI5,$B$5:$B5,$B6),0)/($E6-$D6+1),6),0),ROUND(MAX(AX6-SUMIFS(AI$5:AI5,$B$5:$B5,$B6),0)/($E6-$D6+1),0))))) -> 8 | BB6: =IF($A6="",0,IF('Meta Diária'!M6<>"",'Meta Diária'!M6,IF(AND($C6=1,$A6>='Base de Dados'!$B$6),BT6,0))) -> 0 | BC6: 0 | BD6: =IF($G6=1,IF(BC6<BE6-0.000000001,1,0),"") -> 0 | BE6: =IF($G6=1,SUMIFS(BP$5:BP5,$G$5:$G5,1),"") -> 0 | BF6: =IF($G6=1,IF(AND($E6>=1,($F6-0)>0),IF(BD6=1,ROUNDUP(ROUND((MAX($BB$3-BC6,0)-(0))/($F6-0),6),0),ROUND((MAX($BB$3-BC6,0)-(0))/($F6-0),0)),0),"") -> 5 | BG6: =IF($G6=1,IF(AND($E6>=2,($F6-1)>0),IF(BD6=1,ROUNDUP(ROUND((MAX($BB$3-BC6,0)-(BF6))/($F6-1),6),0),ROUND((MAX($BB$3-BC6,0)-(BF6))/($F6-1),0)),0),"") -> 5 | BH6: =IF($G6=1,IF(AND($E6>=3,($F6-2)>0),IF(BD6=1,ROUNDUP(ROUND((MAX($BB$3-BC6,0)-(BF6+BG6))/($F6-2),6),0),ROUND((MAX($BB$3-BC6,0)-(BF6+BG6))/($F6-2),0)),0),"") -> 0 | BI6: =IF($G6=1,IF(AND($E6>=4,($F6-3)>0),IF(BD6=1,ROUNDUP(ROUND((MAX($BB$3-BC6,0)-(BF6+BG6+BH6))/($F6-3),6),0),ROUND((MAX($BB$3-BC6,0)-(BF6+BG6+BH6))/($F6-3),0)),0),"") -> 0 | BJ6: =IF($G6=1,IF(AND($E6>=5,($F6-4)>0),IF(BD6=1,ROUNDUP(ROUND((MAX($BB$3-BC6,0)-(BF6+BG6+BH6+BI6))/($F6-4),6),0),ROUND((MAX($BB$3-BC6,0)-(BF6+BG6+BH6+BI6))/($F6-4),0)),0),"") -> 0 | BK6: =IF($G6=1,IF(AND($E6>=1,($F6-0)>0),ROUND((($BB$3-BE6)-(0))/($F6-0),0),0),"") -> 5 | BL6: =IF($G6=1,IF(AND($E6>=2,($F6-1)>0),ROUND((($BB$3-BE6)-(BK6))/($F6-1),0),0),"") -> 5 | BM6: =IF($G6=1,IF(AND($E6>=3,($F6-2)>0),ROUND((($BB$3-BE6)-(BK6+BL6))/($F6-2),0),0),"") -> 0 | BN6: =IF($G6=1,IF(AND($E6>=4,($F6-3)>0),ROUND((($BB$3-BE6)-(BK6+BL6+BM6))/($F6-3),0),0),"") -> 0 | BO6: =IF($G6=1,IF(AND($E6>=5,($F6-4)>0),ROUND((($BB$3-BE6)-(BK6+BL6+BM6+BN6))/($F6-4),0),0),"") -> 0 | BP6: =IF($A6="","",IF($G6=1,(BK6+BL6+BM6+BN6+BO6),BP5)) -> 10 | BQ6: =IF($A6="","",IF($G6=1,IF('Base de Dados'!$B$7="Sim",(BF6+BG6+BH6+BI6+BJ6),MAX(BP6,(BF6+BG6+BH6+BI6+BJ6))),BQ5)) -> 10 | BR6: =IF($A6="","",IF($G6=1,BP6,BR5-N(BS5))) -> 10 | BS6: =IF($C6=1,ROUND(BR6/($E6-$D6+1),0),"") -> 5 | BT6: =IF($C6<>1,"",IF('Base de Dados'!$B$7="Sim",IF(SUMIFS(BB$5:BB5,$B$5:$B5,$B6)<SUMIFS(BS$5:BS5,$B$5:$B5,$B6)-0.000000001,ROUNDUP(ROUND(MAX(BQ6-SUMIFS(BB$5:BB5,$B$5:$B5,$B6),0)/($E6-$D6+1),6),0),ROUND(MAX(BQ6-SUMIFS(BB$5:BB5,$B$5:$B5,$B6),0)/($E6-$D6+1),0)),MAX(BS6,IF(SUMIFS(BB$5:BB5,$B$5:$B5,$B6)<SUMIFS(BS$5:BS5,$B$5:$B5,$B6)-0.000000001,ROUNDUP(ROUND(MAX(BQ6-SUMIFS(BB$5:BB5,$B$5:$B5,$B6),0)/($E6-$D6+1),6),0),ROUND(MAX(BQ6-SUMIFS(BB$5:BB5,$B$5:$B5,$B6),0)/($E6-$D6+1),0))))) -> 5 | BU6: =IF($A6="",0,IF('Meta Diária'!O6<>"",'Meta Diária'!O6,IF(AND($C6=1,$A6>='Base de Dados'!$B$6),CM6,0))) -> 0 | BV6: 0 | BW6: =IF($G6=1,IF(BV6<BX6-0.000000001,1,0),"") -> 0 | BX6: =IF($G6=1,SUMIFS(CI$5:CI5,$G$5:$G5,1),"") -> 0 | BY6: =IF($G6=1,IF(AND($E6>=1,($F6-0)>0),IF(BW6=1,ROUNDUP(ROUND((MAX($BU$3-BV6,0)-(0))/($F6-0),6),0),ROUND((MAX($BU$3-BV6,0)-(0))/($F6-0),0)),0),"") -> 2 | BZ6: =IF($G6=1,IF(AND($E6>=2,($F6-1)>0),IF(BW6=1,ROUNDUP(ROUND((MAX($BU$3-BV6,0)-(BY6))/($F6-1),6),0),ROUND((MAX($BU$3-BV6,0)-(BY6))/($F6-1),0)),0),"") -> 2 | CA6: =IF($G6=1,IF(AND($E6>=3,($F6-2)>0),IF(BW6=1,ROUNDUP(ROUND((MAX($BU$3-BV6,0)-(BY6+BZ6))/($F6-2),6),0),ROUND((MAX($BU$3-BV6,0)-(BY6+BZ6))/($F6-2),0)),0),"") -> 0 | CB6: =IF($G6=1,IF(AND($E6>=4,($F6-3)>0),IF(BW6=1,ROUNDUP(ROUND((MAX($BU$3-BV6,0)-(BY6+BZ6+CA6))/($F6-3),6),0),ROUND((MAX($BU$3-BV6,0)-(BY6+BZ6+CA6))/($F6-3),0)),0),"") -> 0 | CC6: =IF($G6=1,IF(AND($E6>=5,($F6-4)>0),IF(BW6=1,ROUNDUP(ROUND((MAX($BU$3-BV6,0)-(BY6+BZ6+CA6+CB6))/($F6-4),6),0),ROUND((MAX($BU$3-BV6,0)-(BY6+BZ6+CA6+CB6))/($F6-4),0)),0),"") -> 0 | CD6: =IF($G6=1,IF(AND($E6>=1,($F6-0)>0),ROUND((($BU$3-BX6)-(0))/($F6-0),0),0),"") -> 2 | CE6: =IF($G6=1,IF(AND($E6>=2,($F6-1)>0),ROUND((($BU$3-BX6)-(CD6))/($F6-1),0),0),"") -> 2 | CF6: =IF($G6=1,IF(AND($E6>=3,($F6-2)>0),ROUND((($BU$3-BX6)-(CD6+CE6))/($F6-2),0),0),"") -> 0 | CG6: =IF($G6=1,IF(AND($E6>=4,($F6-3)>0),ROUND((($BU$3-BX6)-(CD6+CE6+CF6))/($F6-3),0),0),"") -> 0 | CH6: =IF($G6=1,IF(AND($E6>=5,($F6-4)>0),ROUND((($BU$3-BX6)-(CD6+CE6+CF6+CG6))/($F6-4),0),0),"") -> 0 | CI6: =IF($A6="","",IF($G6=1,(CD6+CE6+CF6+CG6+CH6),CI5)) -> 4 | CJ6: =IF($A6="","",IF($G6=1,IF('Base de Dados'!$B$7="Sim",(BY6+BZ6+CA6+CB6+CC6),MAX(CI6,(BY6+BZ6+CA6+CB6+CC6))),CJ5)) -> 4 | CK6: =IF($A6="","",IF($G6=1,CI6,CK5-N(CL5))) -> 4 | CL6: =IF($C6=1,ROUND(CK6/($E6-$D6+1),0),"") -> 2 | CM6: =IF($C6<>1,"",IF('Base de Dados'!$B$7="Sim",IF(SUMIFS(BU$5:BU5,$B$5:$B5,$B6)<SUMIFS(CL$5:CL5,$B$5:$B5,$B6)-0.000000001,ROUNDUP(ROUND(MAX(CJ6-SUMIFS(BU$5:BU5,$B$5:$B5,$B6),0)/($E6-$D6+1),6),0),ROUND(MAX(CJ6-SUMIFS(BU$5:BU5,$B$5:$B5,$B6),0)/($E6-$D6+1),0)),MAX(CL6,IF(SUMIFS(BU$5:BU5,$B$5:$B5,$B6)<SUMIFS(CL$5:CL5,$B$5:$B5,$B6)-0.000000001,ROUNDUP(ROUND(MAX(CJ6-SUMIFS(BU$5:BU5,$B$5:$B5,$B6),0)/($E6-$D6+1),6),0),ROUND(MAX(CJ6-SUMIFS(BU$5:BU5,$B$5:$B5,$B6),0)/($E6-$D6+1),0))))) -> 2
